Exception ignored in: <_io.FileIO name='/home/antoine/dev/python/packages/pyaf/logs/M4_COMP_FINANCE/PyAF_M4_COMP_FINANCE_FIN358_12.log' mode='ab' closefd=True>
ResourceWarning: unclosed file <_io.TextIOWrapper name='/home/antoine/dev/python/packages/pyaf/logs/M4_COMP_FINANCE/PyAF_M4_COMP_FINANCE_FIN358_12.log' mode='a' encoding='UTF-8'>
BENCH_DATA M4_COMP_FINANCE
TIME :  Date N= 489 H= 18 HEAD= [0 1 2 3 4] TAIL= [484 485 486 487 488]
SIGNAL :  FIN366 N= 489 H= 18 HEAD= [-0.07765729  0.05299538 -0.03003101 -0.04987183 -0.09731218] TAIL= [ 0.01744308  0.01111123  0.02237346 -0.01869699  0.00130976]
     FIN366  Date
0 -0.077657     0
1  0.052995     1
2 -0.030031     2
3 -0.049872     3
4 -0.097312     4
<class 'pandas.core.frame.DataFrame'>
Int64Index: 489 entries, 0 to 488
Data columns (total 2 columns):
FIN366    489 non-null float64
Date      489 non-null int64
dtypes: float64(1), int64(1)
memory usage: 11.5 KB
None
BENCHMARK_FAILURE 'M4_COMP_FINANCE_FIN366_18'
