Exception ignored in: <_io.FileIO name='/home/antoine/dev/python/packages/pyaf/logs/M4_COMP_FINANCE/PyAF_M4_COMP_FINANCE_FIN1832_18.log' mode='ab' closefd=True>
ResourceWarning: unclosed file <_io.TextIOWrapper name='/home/antoine/dev/python/packages/pyaf/logs/M4_COMP_FINANCE/PyAF_M4_COMP_FINANCE_FIN1832_18.log' mode='a' encoding='UTF-8'>
BENCH_DATA M4_COMP_FINANCE
TIME :  Date N= 489 H= 18 HEAD= [0 1 2 3 4] TAIL= [484 485 486 487 488]
SIGNAL :  FIN1840 N= 489 H= 18 HEAD= [-0.06773224  0.06876187  0.08264038 -0.06255529 -0.03280904] TAIL= [ 0.01540153 -0.01467652 -0.01225041  0.05439925  0.05370145]
    FIN1840  Date
0 -0.067732     0
1  0.068762     1
2  0.082640     2
3 -0.062555     3
4 -0.032809     4
<class 'pandas.core.frame.DataFrame'>
Int64Index: 489 entries, 0 to 488
Data columns (total 2 columns):
FIN1840    489 non-null float64
Date       489 non-null int64
dtypes: float64(1), int64(1)
memory usage: 11.5 KB
None
BENCHMARK_FAILURE 'M4_COMP_FINANCE_FIN1840_18'
