Exception ignored in: <_io.FileIO name='/home/antoine/dev/python/packages/pyaf/logs/M4_COMP_FINANCE/PyAF_M4_COMP_FINANCE_FIN1804_7.log' mode='ab' closefd=True>
ResourceWarning: unclosed file <_io.TextIOWrapper name='/home/antoine/dev/python/packages/pyaf/logs/M4_COMP_FINANCE/PyAF_M4_COMP_FINANCE_FIN1804_7.log' mode='a' encoding='UTF-8'>
BENCH_DATA M4_COMP_FINANCE
TIME :  Date N= 436 H= 17 HEAD= [0 1 2 3 4] TAIL= [431 432 433 434 435]
SIGNAL :  FIN1814 N= 436 H= 17 HEAD= [ 0.0142243   0.01192128 -0.03761762  0.01921784 -0.05437677] TAIL= [ 0.00739961  0.11008866  0.12405265  0.06062462 -0.05067429]
    FIN1814  Date
0  0.014224     0
1  0.011921     1
2 -0.037618     2
3  0.019218     3
4 -0.054377     4
<class 'pandas.core.frame.DataFrame'>
Int64Index: 436 entries, 0 to 435
Data columns (total 2 columns):
FIN1814    436 non-null float64
Date       436 non-null int64
dtypes: float64(1), int64(1)
memory usage: 10.2 KB
None
BENCHMARK_FAILURE 'M4_COMP_FINANCE_FIN1814_17'
